{
 "cells": [
  {
   "cell_type": "markdown",
   "id": "1c27a7e2-05b2-4041-825b-8ab7131b5f03",
   "metadata": {},
   "source": [
    "# Errors and Exception Handling\n",
    "Errors are an obstacle every programmer will face at least once in their lives so it is best to prepare for this."
   ]
  },
  {
   "cell_type": "code",
   "execution_count": 2,
   "id": "7d3f0f17-140c-43e1-b474-61fc90b00aab",
   "metadata": {},
   "outputs": [
    {
     "ename": "SyntaxError",
     "evalue": "unterminated string literal (detected at line 1) (1679058590.py, line 1)",
     "output_type": "error",
     "traceback": [
      "\u001b[0;36m  Cell \u001b[0;32mIn[2], line 1\u001b[0;36m\u001b[0m\n\u001b[0;31m    print('Hello)\u001b[0m\n\u001b[0m          ^\u001b[0m\n\u001b[0;31mSyntaxError\u001b[0m\u001b[0;31m:\u001b[0m unterminated string literal (detected at line 1)\n"
     ]
    }
   ],
   "source": [
    "print('Hello)"
   ]
  },
  {
   "cell_type": "markdown",
   "id": "90d0f8c5-263f-4b57-b903-a31d4494a66d",
   "metadata": {},
   "source": [
    "Note how we get a SyntaxError, with the further description that it was an EOL (End of Line Error) while scanning the string literal. This is specific enough for us to see that we forgot a single quote at the end of the line. Understanding these various error types will help you debug your code much faster.\n",
    "\n",
    "This type of error and description is known as an Exception. Even if a statement or expression is syntactically correct, it may cause an error when an attempt is made to execute it. Errors detected during execution are called exceptions and are not unconditionally fatal."
   ]
  },
  {
   "cell_type": "markdown",
   "id": "b5564396-ed1a-4828-ad1d-00c043175ad1",
   "metadata": {},
   "source": [
    "## try and except\n",
    "The basic terminology and syntax used to handle errors in Python are the try and except statements. The code which can cause an exception to occur is put in the try block and the handling of the exception is then implemented in the except block of code. "
   ]
  },
  {
   "cell_type": "code",
   "execution_count": 6,
   "id": "8a5e9e71-3fe2-40ef-bd56-c7dc0f02f2b3",
   "metadata": {},
   "outputs": [
    {
     "name": "stdout",
     "output_type": "stream",
     "text": [
      "Content written successfully\n"
     ]
    }
   ],
   "source": [
    "\n",
    "try:\n",
    "    f = open('testfile','w')\n",
    "    f.write('Test write this')\n",
    "except IOError:\n",
    "    # This will only check for an IOError exception and then execute this print statement\n",
    "    print(\"Error: Could not find file or read data\")\n",
    "else:\n",
    "    print(\"Content written successfully\")\n",
    "    f.close()"
   ]
  },
  {
   "cell_type": "markdown",
   "id": "bd35a338-dc18-4bcc-9caa-3f213b703d40",
   "metadata": {},
   "source": [
    "Now let's see what would happen if we did not have write permission (opening only with 'r'):"
   ]
  },
  {
   "cell_type": "code",
   "execution_count": 9,
   "id": "a15dec49-47e4-4de6-ac13-b530c43c99dc",
   "metadata": {},
   "outputs": [
    {
     "name": "stdout",
     "output_type": "stream",
     "text": [
      "Error: Could not find file or read data\n"
     ]
    }
   ],
   "source": [
    "try:\n",
    "    f = open('testfile','r')\n",
    "    f.write('Test write this')\n",
    "except IOError:\n",
    "    # This will only check for an IOError exception and then execute this print statement\n",
    "    print(\"Error: Could not find file or read data\")\n",
    "else:\n",
    "    print(\"Content written successfully\")\n",
    "    f.close()"
   ]
  },
  {
   "cell_type": "markdown",
   "id": "01441840-faa3-419d-9708-b4e212eea3d9",
   "metadata": {},
   "source": [
    "Notice how we only printed a statement. The code still ran and we were able to continue doing actions and running code blocks. This is extremely useful when you have to account for possible input errors in your code. You can be prepared for the error and keep running code, instead of your code just breaking as we saw above.\n",
    "\n",
    "We could have also just said except: if we weren't sure what exception would occur."
   ]
  },
  {
   "cell_type": "code",
   "execution_count": 12,
   "id": "f0215209-5d52-4ac1-9003-827515a8de16",
   "metadata": {},
   "outputs": [
    {
     "name": "stdout",
     "output_type": "stream",
     "text": [
      "Error: Could not find file or read data\n"
     ]
    }
   ],
   "source": [
    "try:\n",
    "    f = open('testfile','r')\n",
    "    f.write('Test write this')\n",
    "except:\n",
    "    # This will check for any exception and then execute this print statement\n",
    "    print(\"Error: Could not find file or read data\")\n",
    "else:\n",
    "    print(\"Content written successfully\")\n",
    "    f.close()"
   ]
  },
  {
   "cell_type": "markdown",
   "id": "3567918d-3942-449a-a5b3-2759668c1978",
   "metadata": {},
   "source": [
    "What if we kept wanting to run code after the exception occurred? This is where finally comes in.\n",
    "\n"
   ]
  },
  {
   "cell_type": "markdown",
   "id": "426f8dcf-7a98-4eba-b9b9-ec13ede3a04c",
   "metadata": {},
   "source": [
    "## finally\n",
    "The finally: block of code will always be run regardless if there was an exception in the try code block. It runs no matter what."
   ]
  },
  {
   "cell_type": "code",
   "execution_count": 16,
   "id": "582b1a68-9c99-4039-8e99-f1637b534a9c",
   "metadata": {},
   "outputs": [
    {
     "name": "stdout",
     "output_type": "stream",
     "text": [
      "Always execute finally code blocks\n"
     ]
    }
   ],
   "source": [
    "try:\n",
    "    f = open(\"testfile\", \"w\")\n",
    "    f.write(\"Test write statement\")\n",
    "    f.close()\n",
    "finally:\n",
    "    print(\"Always execute finally code blocks\")"
   ]
  },
  {
   "cell_type": "markdown",
   "id": "6a37c3c4-d649-411d-94a8-132dc28f739b",
   "metadata": {},
   "source": [
    "We can use this in conjunction with except. Let's see a new example that will take into account a user providing the wrong input:"
   ]
  },
  {
   "cell_type": "code",
   "execution_count": 19,
   "id": "70e55401-0007-427b-9ece-30b507dd43f0",
   "metadata": {},
   "outputs": [],
   "source": [
    "def askint():\n",
    "    try:\n",
    "        val = int(input(\"Please enter an integer: \"))\n",
    "    except:\n",
    "        print(\"Looks like you did not enter an integer!\")\n",
    "\n",
    "    finally:\n",
    "        print(\"Finally, I executed!\")\n",
    "    print(val)"
   ]
  },
  {
   "cell_type": "code",
   "execution_count": 21,
   "id": "fe388dde-21aa-4316-a997-dfec8b044ead",
   "metadata": {},
   "outputs": [
    {
     "name": "stdin",
     "output_type": "stream",
     "text": [
      "Please enter an integer:  1\n"
     ]
    },
    {
     "name": "stdout",
     "output_type": "stream",
     "text": [
      "Finally, I executed!\n",
      "1\n"
     ]
    }
   ],
   "source": [
    "askint()"
   ]
  },
  {
   "cell_type": "code",
   "execution_count": 23,
   "id": "fda02763-62fa-4721-b29b-a3b5167a6ea7",
   "metadata": {},
   "outputs": [
    {
     "name": "stdin",
     "output_type": "stream",
     "text": [
      "Please enter an integer:  five\n"
     ]
    },
    {
     "name": "stdout",
     "output_type": "stream",
     "text": [
      "Looks like you did not enter an integer!\n",
      "Finally, I executed!\n"
     ]
    },
    {
     "ename": "UnboundLocalError",
     "evalue": "cannot access local variable 'val' where it is not associated with a value",
     "output_type": "error",
     "traceback": [
      "\u001b[0;31m---------------------------------------------------------------------------\u001b[0m",
      "\u001b[0;31mUnboundLocalError\u001b[0m                         Traceback (most recent call last)",
      "Cell \u001b[0;32mIn[23], line 1\u001b[0m\n\u001b[0;32m----> 1\u001b[0m askint()\n",
      "Cell \u001b[0;32mIn[19], line 9\u001b[0m, in \u001b[0;36maskint\u001b[0;34m()\u001b[0m\n\u001b[1;32m      7\u001b[0m \u001b[38;5;28;01mfinally\u001b[39;00m:\n\u001b[1;32m      8\u001b[0m     \u001b[38;5;28mprint\u001b[39m(\u001b[38;5;124m\"\u001b[39m\u001b[38;5;124mFinally, I executed!\u001b[39m\u001b[38;5;124m\"\u001b[39m)\n\u001b[0;32m----> 9\u001b[0m \u001b[38;5;28mprint\u001b[39m(val)\n",
      "\u001b[0;31mUnboundLocalError\u001b[0m: cannot access local variable 'val' where it is not associated with a value"
     ]
    }
   ],
   "source": [
    "askint()"
   ]
  },
  {
   "cell_type": "markdown",
   "id": "ca59649b-1468-4f99-a4ed-d26f2aea5877",
   "metadata": {},
   "source": [
    "Notice how we got an error when trying to print val (because it was never properly assigned)."
   ]
  },
  {
   "cell_type": "code",
   "execution_count": 26,
   "id": "bb98da1d-29c4-44fb-abc5-c2621445146e",
   "metadata": {},
   "outputs": [],
   "source": [
    "def askint():\n",
    "    try:\n",
    "        val = int(input(\"Please enter an integer: \"))\n",
    "    except:\n",
    "        print(\"Looks like you did not enter an integer!\")\n",
    "        val = int(input(\"Try again-Please enter an integer: \"))\n",
    "    finally:\n",
    "        print(\"Finally, I executed!\")\n",
    "    print(val)"
   ]
  },
  {
   "cell_type": "code",
   "execution_count": 28,
   "id": "8e205dfa-1dff-43b9-a8fe-68769b58ffa5",
   "metadata": {},
   "outputs": [
    {
     "name": "stdin",
     "output_type": "stream",
     "text": [
      "Please enter an integer:  five\n"
     ]
    },
    {
     "name": "stdout",
     "output_type": "stream",
     "text": [
      "Looks like you did not enter an integer!\n"
     ]
    },
    {
     "name": "stdin",
     "output_type": "stream",
     "text": [
      "Try again-Please enter an integer:  four\n"
     ]
    },
    {
     "name": "stdout",
     "output_type": "stream",
     "text": [
      "Finally, I executed!\n"
     ]
    },
    {
     "ename": "ValueError",
     "evalue": "invalid literal for int() with base 10: 'four'",
     "output_type": "error",
     "traceback": [
      "\u001b[0;31m---------------------------------------------------------------------------\u001b[0m",
      "\u001b[0;31mValueError\u001b[0m                                Traceback (most recent call last)",
      "Cell \u001b[0;32mIn[26], line 3\u001b[0m, in \u001b[0;36maskint\u001b[0;34m()\u001b[0m\n\u001b[1;32m      2\u001b[0m \u001b[38;5;28;01mtry\u001b[39;00m:\n\u001b[0;32m----> 3\u001b[0m     val \u001b[38;5;241m=\u001b[39m \u001b[38;5;28mint\u001b[39m(\u001b[38;5;28minput\u001b[39m(\u001b[38;5;124m\"\u001b[39m\u001b[38;5;124mPlease enter an integer: \u001b[39m\u001b[38;5;124m\"\u001b[39m))\n\u001b[1;32m      4\u001b[0m \u001b[38;5;28;01mexcept\u001b[39;00m:\n",
      "\u001b[0;31mValueError\u001b[0m: invalid literal for int() with base 10: 'five'",
      "\nDuring handling of the above exception, another exception occurred:\n",
      "\u001b[0;31mValueError\u001b[0m                                Traceback (most recent call last)",
      "Cell \u001b[0;32mIn[28], line 1\u001b[0m\n\u001b[0;32m----> 1\u001b[0m askint()\n",
      "Cell \u001b[0;32mIn[26], line 6\u001b[0m, in \u001b[0;36maskint\u001b[0;34m()\u001b[0m\n\u001b[1;32m      4\u001b[0m \u001b[38;5;28;01mexcept\u001b[39;00m:\n\u001b[1;32m      5\u001b[0m     \u001b[38;5;28mprint\u001b[39m(\u001b[38;5;124m\"\u001b[39m\u001b[38;5;124mLooks like you did not enter an integer!\u001b[39m\u001b[38;5;124m\"\u001b[39m)\n\u001b[0;32m----> 6\u001b[0m     val \u001b[38;5;241m=\u001b[39m \u001b[38;5;28mint\u001b[39m(\u001b[38;5;28minput\u001b[39m(\u001b[38;5;124m\"\u001b[39m\u001b[38;5;124mTry again-Please enter an integer: \u001b[39m\u001b[38;5;124m\"\u001b[39m))\n\u001b[1;32m      7\u001b[0m \u001b[38;5;28;01mfinally\u001b[39;00m:\n\u001b[1;32m      8\u001b[0m     \u001b[38;5;28mprint\u001b[39m(\u001b[38;5;124m\"\u001b[39m\u001b[38;5;124mFinally, I executed!\u001b[39m\u001b[38;5;124m\"\u001b[39m)\n",
      "\u001b[0;31mValueError\u001b[0m: invalid literal for int() with base 10: 'four'"
     ]
    }
   ],
   "source": [
    "askint()"
   ]
  },
  {
   "cell_type": "markdown",
   "id": "d0365efa-4941-44f3-9823-bba6c1e3cded",
   "metadata": {},
   "source": [
    "That only did one check. We continually keep checking with a while loop."
   ]
  },
  {
   "cell_type": "code",
   "execution_count": 31,
   "id": "008774f8-85d2-4724-9755-41a50d10ce55",
   "metadata": {},
   "outputs": [],
   "source": [
    "def askint():\n",
    "    while True:\n",
    "        try:\n",
    "            val = int(input(\"Please enter an integer: \"))\n",
    "        except:\n",
    "            print(\"Looks like you did not enter an integer!\")\n",
    "            continue\n",
    "        else:\n",
    "            print(\"Yep that's an integer!\")\n",
    "            break\n",
    "        finally:\n",
    "            print(\"Finally, I executed!\")\n",
    "        print(val)"
   ]
  },
  {
   "cell_type": "code",
   "execution_count": 33,
   "id": "f602c753-1830-4a27-a3e4-9ed0799e7b65",
   "metadata": {},
   "outputs": [
    {
     "name": "stdin",
     "output_type": "stream",
     "text": [
      "Please enter an integer:  1\n"
     ]
    },
    {
     "name": "stdout",
     "output_type": "stream",
     "text": [
      "Yep that's an integer!\n",
      "Finally, I executed!\n"
     ]
    }
   ],
   "source": [
    "askint()"
   ]
  },
  {
   "cell_type": "markdown",
   "id": "3388aee9-97ae-4cce-9fed-b2af007f6152",
   "metadata": {},
   "source": [
    "So why did our function print \"Finally, I executed!\" after each trial, yet it never printed val itself? This is because with a try/except/finally clause, any continue or break statements are reserved until after the try clause is completed. This means that even though a successful input of 3 brought us to the else: block, and a break statement was thrown, the try clause continued through to finally: before breaking out of the while loop. And since print(val) was outside the try clause, the break statement prevented it from running."
   ]
  },
  {
   "cell_type": "code",
   "execution_count": 36,
   "id": "59601165-b5ca-4721-849a-b06e15b0742a",
   "metadata": {},
   "outputs": [],
   "source": [
    "def askint():\n",
    "    while True:\n",
    "        try:\n",
    "            val = int(input(\"Please enter an integer: \"))\n",
    "        except:\n",
    "            print(\"Looks like you did not enter an integer!\")\n",
    "            continue\n",
    "        else:\n",
    "            print(\"Yep that's an integer!\")\n",
    "            print(val)\n",
    "            break\n",
    "        finally:\n",
    "            print(\"Finally, I executed!\")"
   ]
  },
  {
   "cell_type": "code",
   "execution_count": 38,
   "id": "8ff87d2f-6bfe-4763-9bdb-94be6b8c778f",
   "metadata": {},
   "outputs": [
    {
     "name": "stdin",
     "output_type": "stream",
     "text": [
      "Please enter an integer:  six\n"
     ]
    },
    {
     "name": "stdout",
     "output_type": "stream",
     "text": [
      "Looks like you did not enter an integer!\n",
      "Finally, I executed!\n"
     ]
    },
    {
     "name": "stdin",
     "output_type": "stream",
     "text": [
      "Please enter an integer:  6\n"
     ]
    },
    {
     "name": "stdout",
     "output_type": "stream",
     "text": [
      "Yep that's an integer!\n",
      "6\n",
      "Finally, I executed!\n"
     ]
    }
   ],
   "source": [
    "askint()"
   ]
  }
 ],
 "metadata": {
  "kernelspec": {
   "display_name": "Python 3 (ipykernel)",
   "language": "python",
   "name": "python3"
  },
  "language_info": {
   "codemirror_mode": {
    "name": "ipython",
    "version": 3
   },
   "file_extension": ".py",
   "mimetype": "text/x-python",
   "name": "python",
   "nbconvert_exporter": "python",
   "pygments_lexer": "ipython3",
   "version": "3.11.7"
  }
 },
 "nbformat": 4,
 "nbformat_minor": 5
}
